<?xml version="1.0" encoding="UTF-8"?>
<!-- Generated by org.testng.reporters.JUnitReportReporter -->
<testsuite skipped="0" hostname="LAPTOP-BGS5S7GJ" name="com.mtx.autotest05.DouBanTests" tests="3" failures="1" timestamp="16 六月 2020 12:45:35 GMT" time="41.260" errors="0">
  <testcase name="test003_writeDiary" time="9.843" classname="com.mtx.autotest05.DouBanTests">
    <failure type="java.lang.AssertionError" message="实际值【的好与与  183815】与期望值【的好与与 183815】不一致 expected [的好与与 183815] but found [的好与与  183815]">
      <![CDATA[java.lang.AssertionError: 实际值【的好与与  183815】与期望值【的好与与 183815】不一致 expected [的好与与 183815] but found [的好与与  183815]
at org.testng.Assert.fail(Assert.java:96)
at org.testng.Assert.failNotEquals(Assert.java:776)
at org.testng.Assert.assertEqualsImpl(Assert.java:137)
at org.testng.Assert.assertEquals(Assert.java:118)
at org.testng.Assert.assertEquals(Assert.java:453)
at com.crazy.auto.test.Assertion.assertText(Assertion.java:65)
at com.mtx.autotest05.DouBanTests.test003_writeDiary(DouBanTests.java:40)
at sun.reflect.NativeMethodAccessorImpl.invoke0(Native Method)
at sun.reflect.NativeMethodAccessorImpl.invoke(NativeMethodAccessorImpl.java:62)
at sun.reflect.DelegatingMethodAccessorImpl.invoke(DelegatingMethodAccessorImpl.java:43)
at java.lang.reflect.Method.invoke(Method.java:498)
at org.testng.internal.MethodInvocationHelper.invokeMethod(MethodInvocationHelper.java:124)
at org.testng.internal.Invoker.invokeMethod(Invoker.java:580)
at org.testng.internal.Invoker.invokeTestMethod(Invoker.java:716)
at org.testng.internal.Invoker.invokeTestMethods(Invoker.java:988)
at org.testng.internal.TestMethodWorker.invokeTestMethods(TestMethodWorker.java:125)
at org.testng.internal.TestMethodWorker.run(TestMethodWorker.java:109)
at org.testng.TestRunner.privateRun(TestRunner.java:648)
at org.testng.TestRunner.run(TestRunner.java:505)
at org.testng.SuiteRunner.runTest(SuiteRunner.java:455)
at org.testng.SuiteRunner.access$000(SuiteRunner.java:40)
at org.testng.SuiteRunner$SuiteWorker.run(SuiteRunner.java:489)
at org.testng.internal.thread.ThreadUtil$1.call(ThreadUtil.java:52)
at java.util.concurrent.FutureTask.run(FutureTask.java:266)
at java.util.concurrent.ThreadPoolExecutor.runWorker(ThreadPoolExecutor.java:1142)
at java.util.concurrent.ThreadPoolExecutor$Worker.run(ThreadPoolExecutor.java:617)
at java.lang.Thread.run(Thread.java:745)
]]>
    </failure>
  </testcase> <!-- test003_writeDiary -->
  <testcase name="test001_login" time="12.118" classname="com.mtx.autotest05.DouBanTests"/>
  <testcase name="test002_uploadHeaderImg" time="19.299" classname="com.mtx.autotest05.DouBanTests"/>
</testsuite> <!-- com.mtx.autotest05.DouBanTests -->
